Workbook

Sheet Portada
C4: Proyecto: Modelo Financiero y Valoración
C5: VOLCAN COMPAÑÍA MINERA S.A.C
C7: Equipo de análisis:
C8: - Nombre de estudiante 1 | D8: Asencios Huaman, Roberth William
C9: - Nombre de estudiante 2 | D9: Romani Rojas, Renzo Nicolas
C10: - Nombre de estudiante 3 | D10: Rodriguez Alcalde, Jeremias Martin
C12: Leyenda de colores
C13: Azul | D13: Input externos o datos históricos
C14: Negro | D14: Fómula o cálculo
C15: Verde | D15: Fórmula vinculada a otra(s) hoja(s)

Sheet Buildup
C1: Check balance | E1: =ROUND(E53-E85,0) -> 0 | F1: =ROUND(F53-F85,0) -> 0 | G1: =ROUND(G53-G85,0) -> 0 | H1: =ROUND(H53-H85,0) -> 0 | I1: =ROUND(I53-I85,0) -> 0 | J1: =ROUND(J53-J85,0) -> 0 | K1: =ROUND(K53-K85,0) -> 0 | L1: =ROUND(L53-L85,0) -> 0 | ... O1: =ROUND(O53-O85,0) -> 0
B2: VOLCAN COMPAÑÍA MINERA S.A.C | Q2: Análisis vertical histórico | W2: Análisis horizontal histórico
B3: Buildup | E3: 2019 | F3: 2020 | G3: 2021 | H3: 2022 | I3: 2023 | J3: 2024 | K3: 2025 | L3: 2026 | M3: 2027 | N3: 2028 | O3: 2029 | Q3: 2020 | R3: 2021 | S3: 2022 | T3: 2023 | U3: 2024 | W3: '20 vs '19 | X3: '21 vs '20 | Y3: '22 vs '21 | Z3: '23 vs '22 | AA3: '24 vs '23 | AD3: CAGR '19-'24 | AE3: CAGR '24-'29
C4: Unidad | E4: Histórico | F4: Histórico | G4: Histórico | H4: Histórico | I4: Histórico | J4: Histórico | K4: Proyección | L4: Proyección | M4: Proyección | N4: Proyección | O4: Proyección | Q4: % | R4: % | S4: % | T4: % | U4: % | W4: % | X4: % | Y4: % | Z4: % | AA4: % | AD4: % | AE4: %
A5: x | B5: Estados de resultados
B6: Ventas | C6: USD mm | E6: =743578/1000 -> 743.578 | F6: =535469/1000 -> 535.469 | G6: =937399/1000 -> 937.399 | H6: =951266/1000 -> 951.266 | I6: =883086/1000 -> 883.086 | J6: =(960521/1000) -> 960.521 | K6: ='Supuestos '!L14 -> 922.27501 | L6: ='Supuestos '!M14 -> 1065.6195 | M6: ='Supuestos '!N14 -> 1182.8316 | N6: ='Supuestos '!O14 -> 1182.8316 | O6: ='Supuestos '!P14 -> 1221.3316 | Q6: =+F6/$F$6 -> 1 | R6: =+G6/$G$6 -> 1 | S6: =H6/$H$6 -> 1 | T6: =+I6/$I$6 -> 1 | U6: =+J6/$J$6 -> 1 | W6: =+(F6-E6)/E6 -> -0.27987514 | X6: =+(G6-F6)/F6 -> 0.75061301 | Y6: =(H6-G6)/G6 -> 0.01479306 | Z6: =(I6-H6)/H6 -> -0.071672907 | AA6: =(J6-I6)/I6 -> 0.087686816 | AD6: =IFERROR((J6/E6)^(1/(J$3-E$3))-1,"") -> 0.052533837 | AE6: =IFERROR((O6/J6)^(1/(O$3-J$3))-1,"") -> 0.049217067
B7: Costo de ventas | C7: USD mm | E7: =-619985/1000 -> -619.985 | F7: =-513266/1000 -> -513.266 | G7: =-656031/1000 -> -656.031 | H7: =-762743/1000 -> -762.743 | I7: =-(725507/1000) -> -725.507 | J7: =-(699588/1000) -> -699.588 | K7: =-'Supuestos '!L77 -> -571.77992 | L7: =-'Supuestos '!M77 -> -652.31607 | M7: =-'Supuestos '!N77 -> -724.60449 | N7: =-'Supuestos '!O77 -> -727.05096 | O7: =-'Supuestos '!P77 -> -750.15562 | Q7: =+F7/$F$6 -> -0.95853541 | R7: =+G7/$G$6 -> -0.6998418 | S7: =H7/$H$6 -> -0.80181884 | T7: =+I7/$I$6 -> -0.82155872 | U7: =+J7/$J$6 -> -0.72834222 | W7: =+(F7-E7)/E7 -> -0.17213158 | X7: =+(G7-F7)/F7 -> 0.27815012 | Y7: =(H7-G7)/G7 -> 0.16266304 | Z7: =(I7-H7)/H7 -> -0.04881854 | AA7: =(J7-I7)/I7 -> -0.035725362 | AD7: =IFERROR((J7/E7)^(1/(J$3-E$3))-1,"") -> 0.024453461 | AE7: =IFERROR((O7/J7)^(1/(O$3-J$3))-1,"") -> 0.014055681
B8: Utilidad bruta | C8: USD mm | E8: =E6+E7 -> 123.593 | F8: =F6+F7 -> 22.203 | G8: =G6+G7 -> 281.368 | H8: =H6+H7 -> 188.523 | I8: =I6+I7 -> 157.579 | J8: =J6+J7 -> 260.933 | K8: =K6+K7 -> 350.49509 | L8: =L6+L7 -> 413.30342 | ... O8: =O6+O7 -> 471.17599 | AD8: =IFERROR((J8/E8)^(1/(J$3-E$3))-1,"") -> 0.1612 | AE8: =IFERROR((O8/J8)^(1/(O$3-J$3))-1,"") -> 0.12546198
B9: Mg. bruto | C9: % | E9: =IFERROR(E8/E$6,"") -> 0.1662139 | F9: =IFERROR(F8/F$6,"") -> 0.041464585 | G9: =IFERROR(G8/G$6,"") -> 0.3001582 | H9: =IFERROR(H8/H$6,"") -> 0.19818116 | I9: =IFERROR(I8/I$6,"") -> 0.17844128 | J9: =IFERROR(J8/J$6,"") -> 0.27165778 | K9: =IFERROR(K8/K$6,"") -> 0.38003316 | L9: =IFERROR(L8/L$6,"") -> 0.38785272 | ... O9: =IFERROR(O8/O$6,"") -> 0.38578875
AD10: =IFERROR((J10/E10)^(1/(J$3-E$3))-1,"") | AE10: =IFERROR((O10/J10)^(1/(O$3-J$3))-1,"")
B11: Gasto de ventas | C11: USD mm | E11: =-23199/1000 -> -23.199 | F11: =-15435/1000 -> -15.435 | G11: =-21125/1000 -> -21.125 | H11: =-24852/1000 -> -24.852 | I11: =-(30563/1000) -> -30.563 | J11: =-(29081/1000) -> -29.081 | K11: =-'Supuestos '!L87 -> -27.912349 | L11: =-'Supuestos '!M87 -> -33.757614 | M11: =-'Supuestos '!N87 -> -36.334439 | N11: =-'Supuestos '!O87 -> -36.53567 | O11: =-'Supuestos '!P87 -> -37.978573 | Q11: =+F11/$F$6 -> -0.028825198 | R11: =+G11/$G$6 -> -0.022535761 | S11: =H11/$H$6 -> -0.026125185 | T11: =+I11/$I$6 -> -0.034609313 | U11: =+J11/$J$6 -> -0.030276277 | W11: =+(F11-E11)/E11 -> -0.3346696 | X11: =+(G11-F11)/F11 -> 0.3686427 | Y11: =(H11-G11)/G11 -> 0.17642604 | Z11: =(I11-H11)/H11 -> 0.22980042 | AA11: =(J11-I11)/I11 -> -0.048490004 | AD11: =IFERROR((J11/E11)^(1/(J$3-E$3))-1,"") -> 0.046232036 | AE11: =IFERROR((O11/J11)^(1/(O$3-J$3))-1,"") -> 0.054838231
B12: Gasto de administración | C12: USD mm | E12: =-58275/1000 -> -58.275 | F12: =-40752/1000 -> -40.752 | G12: =-57680/1000 -> -57.68 | H12: =-69646/1000 -> -69.646 | I12: =-(55157/1000) -> -55.157 | J12: =-(62875/1000) -> -62.875 | K12: =-'Supuestos '!L96 -> -25.903736 | L12: =-'Supuestos '!M96 -> -30.331794 | M12: =-'Supuestos '!N96 -> -33.465727 | N12: =-'Supuestos '!O96 -> -33.313603 | O12: =-'Supuestos '!P96 -> -32.360325 | Q12: =+F12/$F$6 -> -0.076105246 | R12: =+G12/$G$6 -> -0.061531962 | S12: =H12/$H$6 -> -0.073214012 | T12: =+I12/$I$6 -> -0.062459375 | U12: =+J12/$J$6 -> -0.065459266 | W12: =+(F12-E12)/E12 -> -0.30069498 | X12: =+(G12-F12)/F12 -> 0.41539066 | Y12: =+(H12-G12)/G12 -> 0.20745492 | Z12: =+(I12-H12)/H12 -> -0.20803779 | AA12: =+(J12-I12)/I12 -> 0.13992784 | AD12: =IFERROR((J12/E12)^(1/(J$3-E$3))-1,"") -> 0.015311121 | AE12: =IFERROR((O12/J12)^(1/(O$3-J$3))-1,"") -> -0.12439753
B13: Otros ingresos operativos | C13: USD mm | E13: =66840/1000 -> 66.84 | F13: =46907/1000 -> 46.907 | G13: =42505/1000 -> 42.505 | H13: =60068/1000 -> 60.068 | I13: =63429/1000 -> 63.429 | J13: =145115/1000 -> 145.115 | K13: ='Supuestos '!L102 -> 87.939327 | L13: ='Supuestos '!M102 -> 101.60729 | M13: ='Supuestos '!N102 -> 112.78351 | N13: ='Supuestos '!O102 -> 112.78351 | O13: ='Supuestos '!P102 -> 116.4545 | Q13: =+F13/$F$6 -> 0.087599842 | R13: =+G13/$G$6 -> 0.045343552 | S13: =H13/$H$6 -> 0.063145324 | T13: =+I13/$I$6 -> 0.071826527 | U13: =+J13/$J$6 -> 0.15107947 | W13: =+(F13-E13)/E13 -> -0.29821963 | X13: =+(G13-F13)/F13 -> -0.093845268 | Y13: =+(H13-G13)/G13 -> 0.41319845 | Z13: =+(I13-H13)/H13 -> 0.055953253 | AA13: =+(J13-I13)/I13 -> 1.2878336 | AD13: =IFERROR((J13/E13)^(1/(J$3-E$3))-1,"") -> 0.16771047 | AE13: =IFERROR((O13/J13)^(1/(O$3-J$3))-1,"") -> -0.04305099
B14: Otros gastos operativos | C14: USD mm | E14: =-96341/1000 -> -96.341 | F14: =-97347/1000 -> -97.347 | G14: =-79472/1000 -> -79.472 | H14: =-87465/1000 -> -87.465 | I14: =-(78507/1000) -> -78.507 | J14: =-(115282/1000) -> -115.282 | K14: =-'Supuestos '!L112 -> -89.707902 | L14: =-'Supuestos '!M112 -> -103.60858 | M14: =-'Supuestos '!N112 -> -114.98159 | N14: =-'Supuestos '!O112 -> -115.00624 | O14: =-'Supuestos '!P112 -> -119.21441 | Q14: =+F14/$F$6 -> -0.18179764 | R14: =+G14/$G$6 -> -0.084779267 | S14: =H14/$H$6 -> -0.091945891 | T14: =+I14/$I$6 -> -0.088900741 | U14: =+J14/$J$6 -> -0.12002028 | W14: =+(F14-E14)/E14 -> 0.010442076 | X14: =+(G14-F14)/F14 -> -0.18362148 | Y14: =+(H14-G14)/G14 -> 0.1005763 | Z14: =+(I14-H14)/H14 -> -0.10241811 | AA14: =+(J14-I14)/I14 -> 0.46842957 | AD14: =IFERROR((J14/E14)^(1/(J$3-E$3))-1,"") -> 0.036549557 | AE14: =IFERROR((O14/J14)^(1/(O$3-J$3))-1,"") -> 0.0067310142
B15: Ingreso por reversión de deterioro de activos de larga duración | C15: USD mm | E15: =35600/1000 -> 35.6 | F15: 0 | G15: 0 | H15: 0 | I15: 0 | J15: 0 | K15: 0 | L15: 0 | M15: 0 | N15: 0 | O15: 0 | W15: =+(F15-E15)/E15 -> -1 | AE15: =IFERROR((O15/J15)^(1/(O$3-J$3))-1,"")
B16: Pérdida por deterioro de activos de larga duración | C16: USD mm | E16: =-19613/1000 -> -19.613 | F16: =-10659/1000 -> -10.659 | G16: =-13397/1000 -> -13.397 | H16: =-126069/1000 -> -126.069 | I16: =-(36200/1000) -> -36.2 | J16: =(91700/1000) -> 91.7 | K16: 0 | L16: 0 | M16: 0 | N16: 0 | O16: 0 | Q16: =+F16/$F$6 -> -0.019905914 | R16: =+G16/$G$6 -> -0.014291673 | S16: =H16/$H$6 -> -0.1325276 | T16: =+I16/$I$6 -> -0.04099261 | U16: =+J16/$J$6 -> 0.095469022 | W16: =+(F16-E16)/E16 -> -0.45653393 | X16: =+(G16-F16)/F16 -> 0.25687213 | Y16: =+(H16-G16)/G16 -> 8.4102411 | Z16: =+(I16-H16)/H16 -> -0.71285566 | AA16: =+(J16-I16)/I16 -> -3.5331492 | AD16: =IFERROR((J16/E16)^(1/(J$3-E$3))-1,"") -> -2.3613352 | AE16: =IFERROR((O16/J16)^(1/(O$3-J$3))-1,"") -> -1
B17: Utilidad operativa | C17: USD mm | E17: =SUM(E8,E11:E16) -> 28.605 | F17: =SUM(F8,F11:F16) -> -95.083 | G17: =SUM(G8,G11:G16) -> 152.199 | H17: =SUM(H8,H11:H16) -> -59.441 | I17: =SUM(I8,I11:I16) -> 20.581 | J17: =SUM(J8,J11:J16) -> 290.51 | K17: =SUM(K8,K11:K16) -> 294.91043 | L17: =SUM(L8,L11:L16) -> 347.21272 | ... O17: =SUM(O8,O11:O16) -> 398.07719 | Q17: =+F17/$F$6 -> -0.17756957 | R17: =+G17/$G$6 -> 0.16236309 | S17: =H17/$H$6 -> -0.062486203 | T17: =+I17/$I$6 -> 0.023305771 | U17: =+J17/$J$6 -> 0.30245044 | W17: =+(F17-E17)/E17 -> -4.3239993 | X17: =+(G17-F17)/F17 -> -2.6006962 | Y17: =+(H17-G17)/G17 -> -1.3905479 | Z17: =+(I17-H17)/H17 -> -1.3462425 | AA17: =+(J17-I17)/I17 -> 13.115446 | AD17: =IFERROR((J17/E17)^(1/(J$3-E$3))-1,"") -> 0.58980488 | AE17: =IFERROR((O17/J17)^(1/(O$3-J$3))-1,"") -> 0.065028528
B18: Mg. operativo | C18: % | E18: =IFERROR(E17/E$6,"") -> 0.038469401 | F18: =IFERROR(F17/F$6,"") -> -0.17756957 | G18: =IFERROR(G17/G$6,"") -> 0.16236309 | H18: =IFERROR(H17/H$6,"") -> -0.062486203 | I18: =IFERROR(I17/I$6,"") -> 0.023305771 | J18: =IFERROR(J17/J$6,"") -> 0.30245044 | K18: =IFERROR(K17/K$6,"") -> 0.31976409 | L18: =IFERROR(L17/L$6,"") -> 0.3258318 | ... O18: =IFERROR(O17/O$6,"") -> 0.32593702 | AE18: =IFERROR((O18/J18)^(1/(O$3-J$3))-1,"") -> 0.015069772
AD19: =IFERROR((J19/E19)^(1/(J$3-E$3))-1,"") | AE19: =IFERROR((O19/J19)^(1/(O$3-J$3))-1,"")
B20: D&A | C20: USD mm | E20: =201340/1000 -> 201.34 | F20: =165496/1000 -> 165.496 | G20: =224794/1000 -> 224.794 | H20: =194238/1000 -> 194.238 | I20: =(207115/1000) -> 207.115 | J20: =(194964/1000) -> 194.964 | K20: ='Supuestos '!L119 -> 70.810647 | L20: ='Supuestos '!M119 -> 73.119451 | M20: ='Supuestos '!N119 -> 82.146703 | N20: ='Supuestos '!O119 -> 84.337603 | O20: ='Supuestos '!P119 -> 86.191289 | Q20: =+F20/$F$6 -> 0.30906738 | R20: =+G20/$G$6 -> 0.2398061 | S20: =H20/$H$6 -> 0.20418894 | T20: =+I20/$I$6 -> 0.23453548 | U20: =+J20/$J$6 -> 0.20297734 | W20: =+(F20-E20)/E20 -> -0.17802722 | X20: =+(G20-F20)/F20 -> 0.35830473 | Y20: =+(H20-G20)/G20 -> -0.13592889 | Z20: =+(I20-H20)/H20 -> 0.066294958 | AA20: =+(J20-I20)/I20 -> -0.05866789 | AD20: =IFERROR((J20/E20)^(1/(J$3-E$3))-1,"") -> -0.0064153522 | AE20: =IFERROR((O20/J20)^(1/(O$3-J$3))-1,"") -> -0.15062047
B21: EBITDA | C21: USD mm | E21: =E17+E20 -> 229.945 | F21: =F17+F20 -> 70.413 | G21: =G17+G20 -> 376.993 | H21: =H17+H20 -> 134.797 | I21: =I17+I20 -> 227.696 | J21: =J17+J20 -> 485.474 | K21: =K17+K20 -> 365.72108 | L21: =L17+L20 -> 420.33217 | ... O21: =O17+O20 -> 484.26848 | Q21: =+F21/$F$6 -> 0.13149781 | R21: =+G21/$G$6 -> 0.40216919 | S21: =H21/$H$6 -> 0.14170274 | T21: =+I21/$I$6 -> 0.25784125 | U21: =+J21/$J$6 -> 0.50542778 | W21: =+(F21-E21)/E21 -> -0.6937833 | X21: =+(G21-F21)/F21 -> 4.3540255 | Y21: =+(H21-G21)/G21 -> -0.64244164 | Z21: =+(I21-H21)/H21 -> 0.68917706 | AA21: =+(J21-I21)/I21 -> 1.1321147 | AD21: =IFERROR((J21/E21)^(1/(J$3-E$3))-1,"") -> 0.16120367 | AE21: =IFERROR((O21/J21)^(1/(O$3-J$3))-1,"") -> -0.00049713134
B22: Mg. EBITDA | C22: % | E22: =IFERROR(E21/E$6,"") -> 0.30924126 | F22: =IFERROR(F21/F$6,"") -> 0.13149781 | G22: =IFERROR(G21/G$6,"") -> 0.40216919 | H22: =IFERROR(H21/H$6,"") -> 0.14170274 | I22: =IFERROR(I21/I$6,"") -> 0.25784125 | J22: =IFERROR(J21/J$6,"") -> 0.50542778 | K22: =IFERROR(K21/K$6,"") -> 0.39654232 | L22: =IFERROR(L21/L$6,"") -> 0.39444865 | ... O22: =IFERROR(O21/O$6,"") -> 0.39650859
AD23: =IFERROR((J23/E23)^(1/(J$3-E$3))-1,"") | AE23: =IFERROR((O23/J23)^(1/(O$3-J$3))-1,"")
B24: Ingresos financieros | C24: USD mm | E24: =1842/1000 -> 1.842 | F24: =1820/1000 -> 1.82 | G24: =3179/1000 -> 3.179 | H24: =14751/1000 -> 14.751 | I24: =(5793/1000) -> 5.793 | J24: =(4888/1000) -> 4.888 | K24: ='Supuestos '!L165 -> 155.834 | L24: ='Supuestos '!M165 -> 149.62901 | M24: ='Supuestos '!N165 -> 172.88508 | N24: ='Supuestos '!O165 -> 191.90146 | O24: ='Supuestos '!P165 -> 191.90146 | Q24: =+F24/$F$6 -> 0.0033988896 | R24: =+G24/$G$6 -> 0.0033912987 | S24: =H24/$H$6 -> 0.015506704 | T24: =+I24/$I$6 -> 0.00655995 | U24: =+J24/$J$6 -> 0.0050889049 | W24: =+(F24-E24)/E24 -> -0.01194354 | X24: =+(G24-F24)/F24 -> 0.7467033 | Y24: =+(H24-G24)/G24 -> 3.6401384 | Z24: =+(I24-H24)/H24 -> -0.60728086 | AA24: =+(J24-I24)/I24 -> -0.15622303 | AD24: =IFERROR((J24/E24)^(1/(J$3-E$3))-1,"") -> 0.21553737 | AE24: =IFERROR((O24/J24)^(1/(O$3-J$3))-1,"") -> 1.0834804
B25: Gastos financieros | C25: USD mm | E25: =-48386/1000 -> -48.386 | F25: =-56473/1000 -> -56.473 | G25: =-61591/1000 -> -61.591 | H25: =-57124/1000 -> -57.124 | I25: =-(70526/1000) -> -70.526 | J25: =-(79206/1000) -> -79.206 | K25: =-'Supuestos '!L169 -> -39.662357 | L25: =-'Supuestos '!M169 -> -28.929886 | M25: =-'Supuestos '!N169 -> -19.4558 | N25: =-'Supuestos '!O169 -> -11.504982 | O25: =-'Supuestos '!P169 -> -5.3778645 | Q25: =+F25/$F$6 -> -0.10546456 | R25: =+G25/$G$6 -> -0.065704145 | S25: =H25/$H$6 -> -0.060050501 | T25: =+I25/$I$6 -> -0.079863116 | U25: =+J25/$J$6 -> -0.082461497 | W25: =+(F25-E25)/E25 -> 0.16713512 | X25: =+(G25-F25)/F25 -> 0.090627379 | Y25: =+(H25-G25)/G25 -> -0.07252683 | Z25: =+(I25-H25)/H25 -> 0.23461242 | AA25: =+(J25-I25)/I25 -> 0.12307518 | AD25: =IFERROR((J25/E25)^(1/(J$3-E$3))-1,"") -> 0.10358979 | AE25: =IFERROR((O25/J25)^(1/(O$3-J$3))-1,"") -> -0.41605714
B26: Utilidad antes de impuestos | C26: USD mm | E26: =SUM(E17,E24:E25) -> -17.939 | F26: =SUM(F17,F24:F25) -> -149.736 | G26: =SUM(G17,G24:G25) -> 93.787 | H26: =SUM(H17,H24:H25) -> -101.814 | I26: =SUM(I17,I24:I25) -> -44.152 | J26: =SUM(J17,J24:J25) -> 216.192 | K26: =SUM(K17,K24:K25) -> 411.08207 | L26: =SUM(L17,L24:L25) -> 467.91184 | ... O26: =SUM(O17,O24:O25) -> 584.60078 | Q26: =+F26/$F$6 -> -0.27963524 | R26: =+G26/$G$6 -> 0.10005025 | S26: =H26/$H$6 -> -0.10703 | T26: =+I26/$I$6 -> -0.049997395 | U26: =+J26/$J$6 -> 0.22507785 | W26: =+(F26-E26)/E26 -> 7.3469536 | X26: =+(G26-F26)/F26 -> -1.626349 | Y26: =+(H26-G26)/G26 -> -2.0855876 | Z26: =+(I26-H26)/H26 -> -0.56634647 | AA26: =+(J26-I26)/I26 -> -5.8965392 | AD26: =IFERROR((J26/E26)^(1/(J$3-E$3))-1,"") -> -2.6451605 | AE26: =IFERROR((O26/J26)^(1/(O$3-J$3))-1,"") -> 0.22012396
AD27: =IFERROR((J27/E27)^(1/(J$3-E$3))-1,"") | AE27: =IFERROR((O27/J27)^(1/(O$3-J$3))-1,"")
B28: Impuestos | C28: USD mm | E28: =-52389/1000 -> -52.389 | F28: =-706/1000 -> -0.706 | G28: =-53913/1000 -> -53.913 | H28: =20132/1000 -> 20.132 | I28: =34169/1000 -> 34.169 | J28: =-(79059/1000) -> -79.059 | K28: ='Supuestos '!L178 -> -121.26921 | L28: ='Supuestos '!M178 -> -138.03399 | M28: ='Supuestos '!N178 -> -159.19916 | N28: ='Supuestos '!O178 -> -166.41101 | O28: ='Supuestos '!P178 -> -172.45723 | Q28: =+F28/$F$6 -> -0.0013184704 | R28: =+G28/$G$6 -> -0.057513396 | S28: =H28/$H$6 -> 0.021163376 | T28: =+I28/$I$6 -> 0.038692721 | U28: =+J28/$J$6 -> -0.082308456 | W28: =+(F28-E28)/E28 -> -0.98652389 | X28: =+(G28-F28)/F28 -> 75.364023 | Y28: =+(H28-G28)/G28 -> -1.3734164 | Z28: =+(I28-H28)/H28 -> 0.69724816 | AA28: =+(J28-I28)/I28 -> -3.3137639 | AD28: =IFERROR((J28/E28)^(1/(J$3-E$3))-1,"") -> 0.08578101 | AE28: =IFERROR((O28/J28)^(1/(O$3-J$3))-1,"") -> 0.16881565
B29: Utilidad neta | C29: USD mm | E29: =E26+E28 -> -70.328 | F29: =F26+F28 -> -150.442 | G29: =G26+G28 -> 39.874 | H29: =H26+H28 -> -81.682 | I29: =I26+I28 -> -9.983 | J29: =J26+J28 -> 137.133 | K29: =K26+K28 -> 289.81286 | L29: =L26+L28 -> 329.87785 | ... O29: =O26+O28 -> 412.14355 | Q29: =+F29/$F$6 -> -0.28095371 | R29: =+G29/$G$6 -> 0.042536849 | S29: =H29/$H$6 -> -0.085866624 | T29: =+I29/$I$6 -> -0.011304675 | U29: =+J29/$J$6 -> 0.14276939 | W29: =+(F29-E29)/E29 -> 1.139148 | X29: =+(G29-F29)/F29 -> -1.2650457 | Y29: =+(H29-G29)/G29 -> -3.0485028 | Z29: =+(I29-H29)/H29 -> -0.87778213 | AA29: =+(J29-I29)/I29 -> -14.736652 | AD29: =IFERROR((J29/E29)^(1/(J$3-E$3))-1,"") -> -2.1428856 | AE29: =IFERROR((O29/J29)^(1/(O$3-J$3))-1,"") -> 0.24618152
B30: Mg. neto | C30: % | E30: =IFERROR(E29/E$6,"") -> -0.094580528 | F30: =IFERROR(F29/F$6,"") -> -0.28095371 | G30: =IFERROR(G29/G$6,"") -> 0.042536849 | H30: =IFERROR(H29/H$6,"") -> -0.085866624 | I30: =IFERROR(I29/I$6,"") -> -0.011304675 | J30: =IFERROR(J29/J$6,"") -> 0.14276939 | K30: =IFERROR(K29/K$6,"") -> 0.31423692 | L30: =IFERROR(L29/L$6,"") -> 0.30956439 | ... O30: =IFERROR(O29/O$6,"") -> 0.33745426 | AD30: =IFERROR((J30/E30)^(1/(J$3-E$3))-1,"") -> -2.0858421 | AE30: =IFERROR((O30/J30)^(1/(O$3-J$3))-1,"") -> 0.18772517
AD31: =IFERROR((J31/E31)^(1/(J$3-E$3))-1,"") | AE31: =IFERROR((O31/J31)^(1/(O$3-J$3))-1,"")
A32: x | B32: Balance general | AD32: =IFERROR((J32/E32)^(1/(J$3-E$3))-1,"") | AE32: =IFERROR((O32/J32)^(1/(O$3-J$3))-1,"")
B33: Activos | AD33: =IFERROR((J33/E33)^(1/(J$3-E$3))-1,"") | AE33: =IFERROR((O33/J33)^(1/(O$3-J$3))-1,"")
B34: Activos corrientes | AD34: =IFERROR((J34/E34)^(1/(J$3-E$3))-1,"") | AE34: =IFERROR((O34/J34)^(1/(O$3-J$3))-1,"")
B35: Excedentes | C35: USD mm | E35: 0 | F35: 0 | G35: 0 | H35: 0 | I35: 0 | J35: 0 | K35: =K141 -> 83.921489 | L35: =L141 -> 175.11669 | M35: =M141 -> 288.94676 | N35: =N141 -> 653.61591 | O35: =O141 -> 568.88822 | AD35: =IFERROR((J35/E35)^(1/(J$3-E$3))-1,"") | AE35: =IFERROR((O35/J35)^(1/(O$3-J$3))-1,"")
B36: Efectivo y equivalente de efectivo | C36: USD mm | E36: =33828/1000 -> 33.828 | F36: =114646/1000 -> 114.646 | G36: =231187/1000 -> 231.187 | H36: =73600/1000 -> 73.6 | I36: =61642/1000 -> 61.642 | J36: =(155834/1000) -> 155.834 | K36: ='Supuestos '!L185 -> 149.62901 | L36: ='Supuestos '!M185 -> 172.88508 | M36: ='Supuestos '!N185 -> 191.90146 | N36: ='Supuestos '!O185 -> 191.90146 | O36: ='Supuestos '!P185 -> 198.14766 | Q36: =+F36/$F$53 -> 0.055305937 | R36: =+G36/$G$53 -> 0.10674868 | S36: =H36/$H$53 -> 0.037249075 | T36: =I36/$I$53 -> 0.032872665 | U36: =J36/$J$53 -> 0.084654389 | W36: =+(F36-E36)/E36 -> 2.389086 | X36: =+(G36-F36)/F36 -> 1.0165291 | Y36: =+(H36-G36)/G36 -> -0.681643 | Z36: =+(I36-H36)/H36 -> -0.16247283 | AA36: =+(J36-I36)/I36 -> 1.5280491 | AD36: =IFERROR((J36/E36)^(1/(J$3-E$3))-1,"") -> 0.35730416 | AE36: =IFERROR((O36/J36)^(1/(O$3-J$3))-1,"") -> 0.049217067
A37: Op | B37: Cuentas por cobrar comerciales, neto | C37: USD mm | E37: =36159/1000 -> 36.159 | F37: =28781/1000 -> 28.781 | G37: =43806/1000 -> 43.806 | H37: =28586/1000 -> 28.586 | I37: =(20316/1000) -> 20.316 | J37: =(33477/1000) -> 33.477 | K37: ='Supuestos '!L194 -> 27.025464 | L37: ='Supuestos '!M194 -> 31.225893 | M37: ='Supuestos '!N194 -> 34.660565 | N37: ='Supuestos '!O194 -> 34.660565 | O37: ='Supuestos '!P194 -> 35.788732 | Q37: =+F37/$F$53 -> 0.013884132 | R37: =+G37/$G$53 -> 0.020227057 | S37: =H37/$H$53 -> 0.014467419 | T37: =I37/$I$53 -> 0.010834189 | U37: =J37/$J$53 -> 0.018185858 | W37: =+(F37-E37)/E37 -> -0.20404325 | X37: =+(G37-F37)/F37 -> 0.52204579 | Y37: =+(H37-G37)/G37 -> -0.34744099 | Z37: =+(I37-H37)/H37 -> -0.28930246 | AA37: =+(J37-I37)/I37 -> 0.64781453 | AD37: =IFERROR((J37/E37)^(1/(J$3-E$3))-1,"") -> -0.01529527 | AE37: =IFERROR((O37/J37)^(1/(O$3-J$3))-1,"") -> 0.013444465
A38: Op | B38: Otras cuentas por cobrar, neto | C38: USD mm | E38: =65344/1000 -> 65.344 | F38: =89530/1000 -> 89.53 | G38: =55971/1000 -> 55.971 | H38: =65389/1000 -> 65.389 | I38: =77038/1000 -> 77.038 | J38: =67424/1000 -> 67.424 | K38: ='Supuestos '!L195 -> 0.17736798 | L38: ='Supuestos '!M195 -> 0.20493538 | M38: ='Supuestos '!N195 -> 0.22747711 | N38: ='Supuestos '!O195 -> 0.22747711 | O38: ='Supuestos '!P195 -> 0.23488127 | Q38: =+F38/$F$53 -> 0.043189824 | R38: =+G38/$G$53 -> 0.025844145 | S38: =H38/$H$53 -> 0.033093475 | T38: =I38/$I$53 -> 0.041083099 | U38: =J38/$J$53 -> 0.036627036 | W38: =+(F38-E38)/E38 -> 0.37013345 | X38: =+(G38-F38)/F38 -> -0.37483525 | Y38: =+(H38-G38)/G38 -> 0.16826571 | Z38: =+(I38-H38)/H38 -> 0.17814923 | AA38: =+(J38-I38)/I38 -> -0.12479556 | AD38: =IFERROR((J38/E38)^(1/(J$3-E$3))-1,"") -> 0.0062867623 | AE38: =IFERROR((O38/J38)^(1/(O$3-J$3))-1,"") -> -0.67759128
A39: Op | B39: Otros activos financieros | C39: USD mm | E39: =5416/1000 -> 5.416 | F39: =223/1000 -> 0.223 | G39: 0 | H39: 0 | I39: =655/1000 -> 0.655 | J39: =948/1000 -> 0.948 | K39: ='Supuestos '!L196 -> 0.0021839996 | L39: ='Supuestos '!M196 -> 0.0025234475 | M39: ='Supuestos '!N196 -> 0.0028010125 | N39: ='Supuestos '!O196 -> 0.0028010125 | O39: ='Supuestos '!P196 -> 0.0028921826 | Q39: =+F39/$F$53 -> 0.00010757657 | R39: =+G39/$G$53 -> 0 | S39: =H39/$H$53 -> 0 | T39: =I39/$I$53 -> 0.00034930073 | U39: =J39/$J$53 -> 0.00051498621 | W39: =+(F39-E39)/E39 -> -0.9588257 | X39: =+(G39-F39)/F39 -> -1 | Y39: 0 | Z39: 0 | AA39: =+(J39-I39)/I39 -> 0.44732824 | AD39: =IFERROR((J39/E39)^(1/(J$3-E$3))-1,"") -> -0.29429054 | AE39: =IFERROR((O39/J39)^(1/(O$3-J$3))-1,"") -> -0.68603338
A40: Op | B40: Inventarios, neto | C40: USD mm | E40: =36709/1000 -> 36.709 | F40: =60961/1000 -> 60.961 | G40: =59824/1000 -> 59.824 | H40: =57093/1000 -> 57.093 | I40: =48305/1000 -> 48.305 | J40: =38070/1000 -> 38.07 | K40: ='Supuestos '!L197 -> 47.451933 | L40: ='Supuestos '!M197 -> 54.827144 | M40: ='Supuestos '!N197 -> 60.857819 | N40: ='Supuestos '!O197 -> 60.857819 | O40: ='Supuestos '!P197 -> 62.838681 | Q40: =+F40/$F$53 -> 0.029407962 | R40: =+G40/$G$53 -> 0.027623235 | S40: =H40/$H$53 -> 0.028894856 | T40: =I40/$I$53 -> 0.025760262 | U40: =J40/$J$53 -> 0.020680933 | W40: =+(F40-E40)/E40 -> 0.66065543 | X40: =+(G40-F40)/F40 -> -0.018651269 | Y40: =+(H40-G40)/G40 -> -0.045650575 | Z40: =+(I40-H40)/H40 -> -0.1539243 | AA40: =+(J40-I40)/I40 -> -0.21188283 | AD40: =IFERROR((J40/E40)^(1/(J$3-E$3))-1,"") -> 0.0073074931 | AE40: =IFERROR((O40/J40)^(1/(O$3-J$3))-1,"") -> 0.10542387
...

Sheet Análisis Financiero
B2: VOLCAN COMPAÑÍA MINERA S.A.C
B3: Análisis financiero
E4: 2019 | F4: 2020 | G4: 2021 | H4: 2022 | I4: 2023 | J4: 2024 | K4: 2025 | L4: 2026 | M4: 2027 | N4: 2028 | O4: 2029
C5: Unidad | E5: Histórico | F5: Histórico | G5: Histórico | H5: Histórico | I5: Histórico | J5: Histórico | K5: Proyección | L5: Proyección | M5: Proyección | N5: Proyección | O5: Proyección
A6: x | B6: Indicadores de rentabilidad
B7: Margen bruto | C7: % | E7: =Buildup!E9 -> 0.1662139 | F7: =Buildup!F9 -> 0.041464585 | G7: =Buildup!G9 -> 0.3001582 | H7: =Buildup!H9 -> 0.19818116 | I7: =Buildup!I9 -> 0.17844128 | J7: =Buildup!J9 -> 0.27165778 | K7: =Buildup!K9 -> 0.38003316 | L7: =Buildup!L9 -> 0.38785272 | ... O7: =Buildup!O9 -> 0.38578875
B8: Margen EBITDA | C8: % | E8: =Buildup!E22 -> 0.30924126 | F8: =Buildup!F22 -> 0.13149781 | G8: =Buildup!G22 -> 0.40216919 | H8: =Buildup!H22 -> 0.14170274 | I8: =Buildup!I22 -> 0.25784125 | J8: =Buildup!J22 -> 0.50542778 | K8: =Buildup!K22 -> 0.39654232 | L8: =Buildup!L20 -> 73.119451 | M8: =Buildup!M20 -> 82.146703 | N8: =Buildup!N20 -> 84.337603 | O8: =Buildup!O20 -> 86.191289
B9: Margen operativo | C9: % | K9: =Buildup!K18 -> 0.31976409 | L9: =Buildup!L18 -> 0.3258318 | M9: =Buildup!M18 -> 0.32652905 | N9: =Buildup!N18 -> 0.32439837 | O9: =Buildup!O18 -> 0.32593702
B10: Margen neto | C10: % | E10: =Buildup!E30 -> -0.094580528 | F10: =Buildup!F30 -> -0.28095371 | G10: =Buildup!G30 -> 0.042536849 | H10: =Buildup!H30 -> -0.085866624 | I10: =Buildup!I30 -> -0.011304675 | J10: =Buildup!J30 -> 0.14276939 | K10: =Buildup!K30 -> 0.31423692 | L10: =Buildup!L30 -> 0.30956439 | ... O10: =Buildup!O30 -> 0.33745426
B11: Flujo de caja operativo (FCO) / EBITDA | C11: % | E11: =Buildup!E118/Buildup!E21 -> 1.9309791 | F11: =Buildup!F118/Buildup!F21 -> 3.293994 | G11: =Buildup!G118/Buildup!G21 -> 0.84641625 | H11: =Buildup!H118/Buildup!H21 -> 0.84921771 | I11: =Buildup!I118/Buildup!I21 -> 0.49079474 | J11: =Buildup!J118/Buildup!J21 -> 0.57683625 | K11: =Buildup!K118/Buildup!K21 -> 0.97826412 | L11: =Buildup!L118/Buildup!L21 -> 1.0109769 | ... O11: =Buildup!O118/Buildup!O21 -> 0.57312385
B12: Flujo de caja operativo / Ingresos | C12: % | E12: =E27/Buildup!E6 -> 0.59713843 | F12: =F27/Buildup!F6 -> 0.43315299 | G12: =G27/Buildup!G6 -> 0.34040254 | H12: =H27/Buildup!H6 -> 0.12033648 | I12: =I27/Buildup!I6 -> 0.12654713 | J12: =J27/Buildup!J6 -> 0.29154907 | K12: =Buildup!K118/Buildup!K6 -> 0.38792313 | L12: =Buildup!L118/Buildup!L6 -> 0.39877848 | M12: =Buildup!M118/Buildup!M6 -> 0.40224725 | N12: =Buildup!N118/Buildup!N6 -> 0.60063839 | O12: =Buildup!O118/Buildup!O6 -> 0.22724853
B13: ROA | C13: % | F13: =Buildup!F17/AVERAGE(Buildup!E53:F53) -> -0.044918878 | G13: =Buildup!G17/AVERAGE(Buildup!F53:G53) -> 0.071814762 | H13: =Buildup!H17/AVERAGE(Buildup!G53:H53) -> -0.028704359 | I13: =Buildup!I17/AVERAGE(Buildup!H53:I53) -> 0.010688477 | J13: =Buildup!J17/AVERAGE(Buildup!I53:J53) -> 0.15635625 | K13: =Buildup!K17/AVERAGE(Buildup!J53:K53) -> 0.15540994 | L13: =Buildup!L17/AVERAGE(Buildup!K53:L53) -> 0.16706193 | M13: =Buildup!M17/AVERAGE(Buildup!L53:M53) -> 0.16467524 | ... O13: =Buildup!O17/AVERAGE(Buildup!N53:O53) -> 0.13196965
B14: ROE | C14: % | F14: =Buildup!F29/AVERAGE(Buildup!E83:F83) -> -0.30464638 | G14: =Buildup!G29/AVERAGE(Buildup!F83:G83) -> 0.091287884 | H14: =Buildup!H29/AVERAGE(Buildup!G83:H83) -> -0.19634624 | I14: =Buildup!I29/AVERAGE(Buildup!H83:I83) -> -0.026982868 | J14: =Buildup!J29/AVERAGE(Buildup!I83:J83) -> 0.33681364 | K14: =Buildup!K29/AVERAGE(Buildup!J83:K83) -> 0.48740448 | L14: =Buildup!L29/AVERAGE(Buildup!K83:L83) -> 0.36472766 | M14: =Buildup!M29/AVERAGE(Buildup!L83:M83) -> 0.30204311 | ... O14: =Buildup!O29/AVERAGE(Buildup!N83:O83) -> 0.20069187
A17: x | B17: Indicadores de liquidez
B18: Razon corriente (activos corrientes / pasivos corrientes) | C18: x | E18: =Buildup!E42/Buildup!E64 -> 0.6933643 | F18: =Buildup!F42/Buildup!F64 -> 0.83829753 | G18: =Buildup!G42/Buildup!G64 -> 0.51764525 | H18: =Buildup!H42/Buildup!H64 -> 0.62234386 | I18: =Buildup!I42/Buildup!I64 -> 0.47251881 | J18: =Buildup!J42/Buildup!J64 -> 0.92329329 | K18: =Buildup!K42/Buildup!K64 -> 0.93784157 | L18: =Buildup!L42/Buildup!L64 -> 1.1803901 | ... O18: =Buildup!O42/Buildup!O64 -> 3.063874
B19: Razon acida | C19: x | E19: =(Buildup!E42-Buildup!E40)/Buildup!E64 -> 0.64027611 | F19: =(Buildup!F42-Buildup!F40)/Buildup!F64 -> 0.66455958 | G19: =(Buildup!G42-Buildup!G40)/Buildup!G64 -> 0.43840124 | H19: =(Buildup!H42-Buildup!H40)/Buildup!H64 -> 0.46419282 | I19: =(Buildup!I42-Buildup!I40)/Buildup!I64 -> 0.36275991 | J19: =(Buildup!J42-Buildup!J40)/Buildup!J64 -> 0.80444487 | K19: =(Buildup!K42-Buildup!K40)/Buildup!K64 -> 0.79345052 | L19: =(Buildup!L42-Buildup!L40)/Buildup!L64 -> 1.0313617 | ... O19: =(Buildup!O42-Buildup!O40)/Buildup!O64 -> 2.8415278
B21: Capital de trabajo | C21: USD mm | D21: us | E21: =Buildup!E37+Buildup!E40-Buildup!E59 -> -105.307 | F21: =Buildup!F37+Buildup!F40-Buildup!F59 -> -132.898 | G21: =Buildup!G37+Buildup!G40-Buildup!G59 -> -126.063 | H21: =Buildup!H37+Buildup!H40-Buildup!H59 -> -165.56 | I21: =Buildup!I37+Buildup!I40-Buildup!I59 -> -173.592 | J21: =Buildup!J37+Buildup!J40-Buildup!J59 -> -118.164 | K21: =Buildup!K37+Buildup!K40-Buildup!K59 -> -138.8104 | L21: =Buildup!L37+Buildup!L40-Buildup!L59 -> -160.38499 | ... O21: =Buildup!O37+Buildup!O40-Buildup!O59 -> -183.82101
B22: Días de rotación de cuentas por cobrar | C22: días | E22: =(Buildup!E37/Buildup!E6)*365 -> 17.749362 | F22: =(Buildup!F37/Buildup!F6)*365 -> 19.618437 | G22: =(Buildup!G37/Buildup!G6)*365 -> 17.056974 | H22: =(Buildup!H37/Buildup!H6)*365 -> 10.968425 | I22: =(Buildup!I37/Buildup!I6)*365 -> 8.3970757 | J22: =(Buildup!J37/Buildup!J6)*365 -> 12.72133 | K22: =(Buildup!K37/Buildup!K6)*365 -> 10.69561 | L22: 10.7 | M22: =(Buildup!M37/Buildup!M6)*365 -> 10.69561 | N22: =(Buildup!N37/Buildup!N6)*365 -> 10.69561 | O22: =(Buildup!O37/Buildup!O6)*365 -> 10.69561
B23: Días de rotación de inventarios | C23: días | E23: =-Buildup!E40/Buildup!E7*365 -> 21.611466 | F23: =-Buildup!F40/Buildup!F7*365 -> 43.351332 | G23: =-Buildup!G40/Buildup!G7*365 -> 33.284647 | H23: =-Buildup!H40/Buildup!H7*365 -> 27.321057 | I23: =-Buildup!I40/Buildup!I7*365 -> 24.302074 | J23: =-Buildup!J40/Buildup!J7*365 -> 19.862476 | K23: =-Buildup!K40/Buildup!K7*365 -> 30.291297 | L23: =-Buildup!L40/Buildup!L7*365 -> 30.678238 | ... O23: =-Buildup!O40/Buildup!O7*365 -> 30.575148
B24: Días de rotación de cuentas por pagar | C24: días | E24: =-Buildup!E59/Buildup!E7*365 -> 104.89588 | F24: =-Buildup!F59/Buildup!F7*365 -> 158.32648 | G24: =-Buildup!G59/Buildup!G7*365 -> 127.79571 | H24: =-Buildup!H59/Buildup!H7*365 -> 120.22691 | I24: =-Buildup!I59/Buildup!I7*365 -> 121.8565 | J24: =-Buildup!J59/Buildup!J7*365 -> 98.978992 | K24: =-Buildup!K59/Buildup!K7*365 -> 136.15386 | L24: =-Buildup!L59/Buildup!L7*365 -> 137.89309 | ... O24: =-Buildup!O59/Buildup!O7*365 -> 137.42972
B25: Ciclo de conversión de efectivo | C25: días | E25: =(Buildup!E46+Buildup!F46)*365/(2*Buildup!F7)+(Buildup!E37+Buildup!F37)*365/(2*Buildup!F6)-(Buildup!E59+Buildup!F59)*365/(2*Buildup!F7) -> 162.13292 | F25: =(Buildup!F46+Buildup!G46)*365/(2*Buildup!G7)+(Buildup!F37+Buildup!G37)*365/(2*Buildup!G6)-(Buildup!F59+Buildup!G59)*365/(2*Buildup!G7) -> 136.14898 | G25: =(Buildup!G46+Buildup!H46)*365/(2*Buildup!H7)+(Buildup!G37+Buildup!H37)*365/(2*Buildup!H6)-(Buildup!G59+Buildup!H59)*365/(2*Buildup!H7) -> 125.88303 | H25: =(Buildup!H46+Buildup!I46)*365/(2*Buildup!I7)+(Buildup!H37+Buildup!I37)*365/(2*Buildup!I6)-(Buildup!H59+Buildup!I59)*365/(2*Buildup!I7) -> 131.25557 | I25: =(Buildup!I46+Buildup!J46)*365/(2*Buildup!J7)+(Buildup!I37+Buildup!J37)*365/(2*Buildup!J6)-(Buildup!I59+Buildup!J59)*365/(2*Buildup!J7) -> 120.07869 | K25: =(Buildup!K46+Buildup!L46)*365/(2*Buildup!L7)+(Buildup!K37+Buildup!L37)*365/(2*Buildup!L6)-(Buildup!K59+Buildup!L59)*365/(2*Buildup!L7) -> 135.69637 | L25: =(Buildup!L46+Buildup!M46)*365/(2*Buildup!M7)+(Buildup!L37+Buildup!M37)*365/(2*Buildup!M6)-(Buildup!L59+Buildup!M59)*365/(2*Buildup!M7) -> 138.52006 | M25: =(Buildup!M46+Buildup!N46)*365/(2*Buildup!N7)+(Buildup!M37+Buildup!N37)*365/(2*Buildup!N6)-(Buildup!M59+Buildup!N59)*365/(2*Buildup!N7) -> 202.9482 | N25: =(Buildup!N46+Buildup!O46)*365/(2*Buildup!O7)+(Buildup!N37+Buildup!O37)*365/(2*Buildup!O6)-(Buildup!N59+Buildup!O59)*365/(2*Buildup!O7) -> 199.02437
B27: Flujo de caja operativo (FCO) | C27: USD mm | E27: =Buildup!E118 -> 444.019 | F27: =Buildup!F118 -> 231.94 | G27: =Buildup!G118 -> 319.093 | H27: =Buildup!H118 -> 114.472 | I27: =Buildup!I118 -> 111.752 | J27: =Buildup!J118 -> 280.039 | K27: =Buildup!K118 -> 357.77181 | L27: =Buildup!L118 -> 424.94613 | ... O27: =Buildup!O118 -> 277.54582
A29: x | B29: Solvencia
B31: Estructura de capital y endeudamiento:
B32: Pasivos / Patrimonio | C32: x | F32: =Buildup!F74/Buildup!F83 -> 3.9720259 | G32: =Buildup!G74/Buildup!G83 -> 3.7419958 | H32: =Buildup!H74/Buildup!H83 -> 4.2643458 | I32: =Buildup!I74/Buildup!I83 -> 4.1430617 | J32: =Buildup!J74/Buildup!J83 -> 3.0935272 | K32: =Buildup!K74/Buildup!K83 -> 1.6428716 | L32: =Buildup!L74/Buildup!L83 -> 1.0593657 | M32: =Buildup!M74/Buildup!M83 -> 0.71640951 | ... O32: =Buildup!O74/Buildup!O83 -> 0.34756239
B33: Pasivos / Activos | C33: % | F33: =Buildup!F74/Buildup!F53 -> 0.79887474 | G33: =Buildup!G74/Buildup!G53 -> 0.78904546 | H33: =Buildup!H74/Buildup!H53 -> 0.81008387 | I33: =Buildup!I74/Buildup!I53 -> 0.80555255 | J33: =Buildup!J74/Buildup!J53 -> 0.75572216 | K33: =Buildup!K74/Buildup!K53 -> 0.62162369 | L33: =Buildup!L74/Buildup!L53 -> 0.5144136 | M33: =Buildup!M74/Buildup!M53 -> 0.41738845 | ... O33: =Buildup!O74/Buildup!O53 -> 0.25791933
B34: Deuda / EBITDA | C34: x | F34: =(Buildup!F57+Buildup!F67)/Buildup!F21 -> 13.148055 | G34: =(Buildup!G57+Buildup!G67)/Buildup!G21 -> 2.4840116 | H34: =(Buildup!H57+Buildup!H67)/Buildup!H21 -> 6.0199263 | I34: =(Buildup!I57+Buildup!I67)/Buildup!I21 -> 3.5304485 | J34: =(Buildup!J57+Buildup!J67)/Buildup!J21 -> 1.5443896 | K34: =(Buildup!K57+Buildup!K67)/Buildup!K21 -> 1.7508823 | L34: =(Buildup!L57+Buildup!L67)/Buildup!L21 -> 1.2492964 | M34: =(Buildup!M57+Buildup!M67)/Buildup!M21 -> 0.86214898 | ... O34: =(Buildup!O57+Buildup!O67)/Buildup!O21 -> 0.29239615
B36: Cobertura
B37: EBITDA / Gastos financiero | C37: x | F37: =-Buildup!F21/Buildup!F25 -> 1.2468436 | G37: =-Buildup!G21/Buildup!G25 -> 6.1209105 | H37: =-Buildup!H21/Buildup!H25 -> 2.3597262 | I37: =-Buildup!I21/Buildup!I25 -> 3.2285398 | J37: =-Buildup!J21/Buildup!J25 -> 6.1292579 | K37: =-Buildup!K21/Buildup!K25 -> 9.2208609 | L37: =-Buildup!L21/Buildup!L25 -> 14.529341 | M37: =-Buildup!M21/Buildup!M25 -> 24.073827 | ... O37: =-Buildup!O21/Buildup!O25 -> 90.048472
B38: EBITDA / Servicio de deuda | C38: x | F38: =Buildup!F21/(Buildup!F25+(Buildup!E57-Buildup!F53)) -> -0.036963388 | G38: =Buildup!G21/(Buildup!G25+(Buildup!F57-Buildup!G53)) -> -0.1721331 | H38: =Buildup!H21/(Buildup!H25+(Buildup!G57-Buildup!H53)) -> -0.085213811 | I38: =Buildup!I21/(Buildup!I25+(Buildup!H57-Buildup!I53)) -> -0.11914993 | J38: =Buildup!J21/(Buildup!J25+(Buildup!I57-Buildup!J53)) -> -0.27217154 | K38: =Buildup!K21/(Buildup!K25+(Buildup!J57-Buildup!K53)) -> -0.18722345 | L38: =Buildup!L21/(Buildup!L25+(Buildup!K57-Buildup!L53)) -> -0.19864683 | M38: =Buildup!M21/(Buildup!M25+(Buildup!L57-Buildup!M53)) -> -0.1962458 | ... O38: =Buildup!O21/(Buildup!O25+(Buildup!N57-Buildup!O53)) -> -0.1660751
A40: x | B40: Fin

Sheet Hoja2
D4: 000 dolares
D5: 2024 | E5: 2023 | F5: 2022 | G5: 2021 | H5: 2020 | I5: 2019
C6: COSTO DE VENTAS | E6: =+SUM(E7:E11)/1000 -> 199.51 | F6: =+SUM(F7:F11)/1000 -> 218.859 | G6: =+SUM(G7:G11)/1000 -> 187.514 | H6: =+SUM(H7:H11)/1000 -> 157.647 | I6: =+SUM(I7:I11)/1000 -> 194.488
B7: =+D7+D10 -> 108424 | C7: dep | D7: 102935 | E7: 103455 | F7: 106245 | G7: 88788 | H7: 74415 | I7: 105200
C8: dep uso | D8: 6700 | E8: 4568 | F8: 5952 | G8: 4058 | H8: 15350 | I8: 18302
C9: amo | D9: 68515 | E9: 88829 | F9: 104267 | G9: 90736 | H9: 42387 | I9: 66534
C10: dep planta paraliza | D10: 5489 | E10: 1785 | F10: 1619 | G10: 3237 | H10: 22774 | I10: 3032
C11: amor plant parali | D11: 4703 | E11: 873 | F11: 776 | G11: 695 | H11: 2721 | I11: 1420
C13: GASTOS ADM
C14: amor | D14: 2063 | E14: 2559 | F14: 409 | G14: 1123 | H14: 1225 | I14: 622
C15: dep uso | D15: 744 | E15: 870 | F15: 1134 | G15: 768 | H15: 868 | I15: 522
C16: dep | D16: 720 | E16: 1528 | F16: 229 | G16: 810 | H16: 860 | I16: 1193
C18: GASTOS DE VENTAS
C19: dep | D19: 66 | E19: 43 | F19: 96 | G19: 91 | H19: 80 | I19: 44
C22: OTROS GASTOS
C23: dep | D23: 2625 | E23: 2411 | F23: 3264 | G23: 3741 | H23: 4554 | I23: 3987
C24: amo | D24: 404 | E24: 194 | F24: 803 | G24: 191 | H24: 262 | I24: 484
D26: =+SUM(D7:D24) -> 194964 | E26: =+SUM(E7:E24) -> 207115 | F26: =+SUM(F7:F24) -> 224794 | G26: =+SUM(G7:G24) -> 194238 | H26: =+SUM(H7:H24) -> 165496 | I26: =+SUM(I7:I24) -> 201340
D27: =+D26/1000 -> 194.964 | E27: =+E26/1000 -> 207.115 | F27: =+F26/1000 -> 224.794 | G27: =+G26/1000 -> 194.238 | H27: =+H26/1000 -> 165.496 | I27: =+I26/1000 -> 201.34

Sheet Supuestos 
B2: Minera Volcan | F2: Históricos | L2: Proyecciones
B3: Supuestos y drivers | D3: Año | F3: 2019 | G3: 2020 | H3: 2021 | I3: 2022 | J3: 2023 | K3: 2024 | L3: =K3+1 -> 2025 | M3: =L3+1 -> 2026 | N3: =M3+1 -> 2027 | O3: =N3+1 -> 2028 | P3: =O3+1 -> 2029
D4: Mes | F4: 43830 | G4: 44196 | H4: 44561 | I4: 44926 | J4: 45291 | K4: 45657 | L4: 46022 | M4: 46387 | N4: 46752 | O4: 47118 | P4: 47483
A5: x | B5: Indicadores macroecónomicos
B7: Inflación promedia (AoP) - BCRP | F7: 0.024 | G7: 0.02 | H7: 0.064 | I7: 0.085 | J7: 0.032 | K7: 0.02 | L7: 0.017 | M7: 0.02 | N7: 0.02 | O7: 0.02 | P7: 0.02
B8: Variación del PBI minería Perú | D8: % | F8: - | G8: -0.134 | H8: 0.081 | I8: 0.005 | J8: 0.081 | K8: 0.022 | L8: 0.02 | M8: 0.048 | N8: 0.015 | O8: 0.013 | P8: 0.015
A10: x | B10: Estados de Resultados
A12: x | B12: A) Ventas
B14: Ventas | D14: Miles | F14: =+Buildup!E6 -> 743.578 | G14: =+Buildup!F6 -> 535.469 | H14: =+Buildup!G6 -> 937.399 | I14: =+Buildup!H6 -> 951.266 | J14: =+Buildup!I6 -> 883.086 | K14: =+Buildup!J6 -> 960.521 | L14: =+(L18+L31+L44+L57)/1000 -> 922.27501 | M14: =+(M18+M31+M44+M57)/1000 -> 1065.6195 | N14: =+(N18+N31+N44+N57)/1000 -> 1182.8316 | O14: =+(O18+O31+O44+O57)/1000 -> 1182.8316 | P14: =+(P18+P31+P44+P57)/1000 -> 1221.3316
B15: Variación anual | D15: % | F15: =IFERROR(F14/#REF!-1," ") | G15: =IFERROR(G14/F14-1," ") -> -0.27987514 | H15: =IFERROR(H14/G14-1," ") -> 0.75061301 | I15: =IFERROR(I14/H14-1," ") -> 0.01479306 | J15: =IFERROR(J14/I14-1," ") -> -0.071672907 | K15: =IFERROR(K14/J14-1," ") -> 0.087686816 | L15: =IFERROR(L14/K14-1," ") -> -0.039817962 | M15: =IFERROR(M14/L14-1," ") -> 0.15542488 | N15: =IFERROR(N14/M14-1," ") -> 0.10999434 | ... P15: =IFERROR(P14/O14-1," ") -> 0.032549012
B17: Zinc
B18: Ventas por zinc | F18: =+F20*F22 -> 612660.7 | G18: =+G20*G22 -> 379620 | H18: =+H20*H22 -> 661483.9 | I18: =+I20*I22 -> 771541.3 | J18: =+J20*J22 -> 645176.4 | K18: =+K20*K22 -> 653801.6 | L18: =+L20*L22 -> 708894.13 | M18: =+M20*M22 -> 777021.8 | ... P18: =+P20*P22 -> 859521.8
B19: Variación anual(%) | D19: % | G19: =+G18/F18-1 -> -0.38037481 | H19: =+H18/G18-1 -> 0.74248959 | I19: =+I18/H18-1 -> 0.16637956 | J19: =+J18/I18-1 -> -0.16378242 | K19: =+K18/J18-1 -> 0.013368747 | L19: =+L18/K18-1 -> 0.084264908 | M19: =+M18/L18-1 -> 0.096104152 | N19: =+N18/M18-1 -> 0.056626468 | ... P19: =+P18/O18-1 -> 0.046892786
B20: Precio | D20: US$/TM | F20: 2539 | G20: 2280 | H20: 2981 | I20: 3449 | J20: 2642 | K20: 2768 | L20: 2700 | M20: 2750 | N20: 2750 | O20: 2750 | P20: 2750
B21: Variación anual(%) | D21: % | G21: =+G20/F20-1 -> -0.10200866 | H21: =+H20/G20-1 -> 0.30745614 | I21: =+I20/H20-1 -> 0.1569943 | J21: =+J20/I20-1 -> -0.23398086 | K21: =+K20/J20-1 -> 0.047691143 | L21: =+L20/K20-1 -> -0.024566474 | M21: =+M20/L20-1 -> 0.018518519 | N21: =+N20/M20-1 -> 0 | ... P21: =+P20/O20-1 -> 0
B22: Volumen de venta | D22: Miles TMF | F22: 241.3 | G22: 166.5 | H22: 221.9 | I22: 223.7 | J22: 244.2 | K22: 236.2 | L22: =+L27+L29 -> 262.55338 | M22: =+M27+M28 -> 282.55338 | N22: =+N27+N28 -> 298.55338 | O22: =+O27+O28 -> 298.55338 | P22: =+P27+P28 -> 312.55338
B24: Reservas total de cobre | F24: 1565 | G24: 1274 | H24: 1091 | I24: 1162 | J24: 1162 | K24: 1924
B25: % de uso | F25: =+F22/AVERAGE(D24:F24) -> 0.1541853 | G25: =+G22/AVERAGE(F24:G24) -> 0.11729482 | H25: =+H22/AVERAGE(G24:H24) -> 0.18765328 | I25: =+I22/AVERAGE(H24:I24) -> 0.19857967 | J25: =+J22/AVERAGE(I24:J24) -> 0.21015491 | K25: =+K22/AVERAGE(J24:K24) -> 0.15307842
B27: Cantidad vendida por reservas existentes | C27: =+AVERAGE(F25:K25) -> 0.17015773 | L27: =+$C$27*AVERAGE($J$24:$K$24) -> 262.55338 | M27: =+$C$27*AVERAGE($J$24:$K$24) -> 262.55338 | N27: =+$C$27*AVERAGE($J$24:$K$24) -> 262.55338 | O27: =+$C$27*AVERAGE($J$24:$K$24) -> 262.55338 | P27: =+$C$27*AVERAGE($J$24:$K$24) -> 262.55338
B28: Producción por nuevas reservas | D28: Miles TMF | L28: 0 | M28: 20 | N28: 36 | O28: 36 | P28: 50
B30: Plomo
B31: Ventas por Plomo | F31: =+F33*F35 -> 128219.5 | G31: =+G33*G35 -> 83516.4 | H31: =+H33*H35 -> 102508.8 | I31: =+I33*I35 -> 122505.7 | J31: =+J33*J35 -> 129625.6 | K31: =+K33*K35 -> 114913.4 | L31: =+L33*L35 -> 166636.43 | M31: =+M33*M35 -> 188136.43 | ... P31: =+P33*P35 -> 209636.43
B32: Variación anual (%) | D32: % | G32: =+G31/F31-1 -> -0.3486451 | H32: =+H31/G31-1 -> 0.22740923 | I32: =+I31/H31-1 -> 0.19507496 | J32: =+J31/I31-1 -> 0.058118928 | K32: =+K31/J31-1 -> -0.11349764 | L32: =+L31/K31-1 -> 0.45010446 | M32: =+M31/L31-1 -> 0.1290234 | N32: =+N31/M31-1 -> 0.11427877 | ... P32: =+P31/O31-1 -> 0
B33: Precio | D33: US$/TM | F33: 2539 | G33: 1998 | H33: 1824 | I33: 2153 | J33: 2132 | K33: 2078 | L33: 2150 | M33: 2150 | N33: 2150 | O33: 2150 | P33: 2150
B34: Variación anual (%) | D34: % | G34: =+G33/F33-1 -> -0.21307601 | H34: =+H33/G33-1 -> -0.087087087 | I34: =+I33/H33-1 -> 0.18037281 | J34: =+J33/I33-1 -> -0.0097538319 | K34: =+K33/J33-1 -> -0.02532833 | L34: =+L33/K33-1 -> 0.034648701 | M34: =+M33/L33-1 -> 0 | N34: =+N33/M33-1 -> 0 | ... P34: =+P33/O33-1 -> 0
B35: Volumen de venta | D35: Miles TMF | F35: 50.5 | G35: 41.8 | H35: 56.2 | I35: 56.9 | J35: 60.8 | K35: 55.3 | L35: =+L40+L41 -> 77.505318 | M35: =+M40+M41 -> 87.505318 | N35: =+N40+N41 -> 97.505318 | O35: =+O40+O41 -> 97.505318 | P35: =+P40+P41 -> 97.505318
B37: Reservas total de plomo | F37: 371 | G37: 299 | H37: 231 | I37: 279 | J37: 275 | K37: 620
B38: % de uso | F38: =+F35/AVERAGE(D37:F37) -> 0.1361186 | G38: =+G35/AVERAGE(F37:G37) -> 0.12477612 | H38: =+H35/AVERAGE(G37:H37) -> 0.21207547 | I38: =+I35/AVERAGE(H37:I37) -> 0.22313725 | J38: =+J35/AVERAGE(I37:J37) -> 0.21949458 | K38: =+K35/AVERAGE(J37:K37) -> 0.12357542
B40: Cantidad vendida por reservas existentes | C40: =+AVERAGE(F38:K38) -> 0.17319624 | L40: =+$C$40*AVERAGE($J$37:$K$37) -> 77.505318 | M40: =+$C$40*AVERAGE($J$37:$K$37) -> 77.505318 | N40: =+$C$40*AVERAGE($J$37:$K$37) -> 77.505318 | O40: =+$C$40*AVERAGE($J$37:$K$37) -> 77.505318 | P40: =+$C$40*AVERAGE($J$37:$K$37) -> 77.505318
B41: Producción por nuevas reservas | D41: Miles TMF | L41: 0 | M41: =20*50% -> 10 | N41: 20 | O41: 20 | P41: 20
B43: Cobre
B44: Ventas por Cobre | F44: =+F46*F48 -> 25894.6 | G44: =+G46*G48 -> 19436.8 | H44: =+H46*H48 -> 37206 | I44: =+I46*I48 -> 43013.4 | J44: =+J46*J48 -> 47196.8 | K44: =+K46*K48 -> 42630 | L44: =+L46*L48 -> 46292.412 | M44: =+M46*M48 -> 100049.85 | ... P44: =+P46*P48 -> 151749.85
B45: Variación anual(%) | D45: % | G45: =+G44/F44-1 -> -0.2493879 | H45: =+H44/G44-1 -> 0.91420398 | I45: =+I44/H44-1 -> 0.15608773 | J45: =+J44/I44-1 -> 0.097258064 | K45: =+K44/J44-1 -> -0.096760797 | L45: =+L44/K44-1 -> 0.085911617 | M45: =+M44/L44-1 -> 1.1612581 | N45: =+N44/M44-1 -> 0.51674239 | ... P45: =+P44/O44-1 -> 0
B46: Precio | D46: US$/TM | F46: 6022 | G46: 6074 | H46: 8268 | I46: 8434 | J46: 8428 | K46: 8700 | L46: 9000 | M46: 9400 | N46: 9400 | O46: 9400 | P46: 9400
B47: Variación anual(%) | D47: % | G47: =+G46/F46-1 -> 0.008635005 | H47: =+H46/G46-1 -> 0.36121172 | I47: =+I46/H46-1 -> 0.020077407 | J47: =+J46/I46-1 -> -0.00071140621 | K47: =+K46/J46-1 -> 0.032273374 | L47: =+L46/K46-1 -> 0.034482759 | M47: =+M46/L46-1 -> 0.044444444 | N47: =+N46/M46-1 -> 0 | ... P47: =+P46/O46-1 -> 0
B48: Volumen de venta | D48: Miles TMF | F48: 4.3 | G48: 3.2 | H48: 4.5 | I48: 5.1 | J48: 5.6 | K48: 4.9 | L48: =+L53+L54 -> 5.1436014 | M48: =+M53+M54 -> 10.643601 | N48: =+N53+N54 -> 16.143601 | O48: =+O53+O54 -> 16.143601 | P48: =+P53+P54 -> 16.143601
B50: Reservas total de cobre | D50: Miles TMF | F50: 65.4 | G50: 27.7 | H50: 23.5 | I50: 31.5 | J50: 29.7 | K50: 46.8
B51: % de uso | F51: =+F48/AVERAGE(D50:F50) -> 0.065749235 | G51: =+G48/AVERAGE(F50:G50) -> 0.068743287 | H51: =+H48/AVERAGE(G50:H50) -> 0.17578125 | I51: =+I48/AVERAGE(H50:I50) -> 0.18545455 | J51: =+J48/AVERAGE(I50:J50) -> 0.18300654 | K51: =+K48/AVERAGE(J50:K50) -> 0.12810458
B53: Cantidad vendida por reservas existentes | C53: =+AVERAGE(F51:K51) -> 0.13447324 | L53: =+$C$53*AVERAGE($J$50:$K$50) -> 5.1436014 | M53: =+$C$53*AVERAGE($J$50:$K$50) -> 5.1436014 | N53: =+$C$53*AVERAGE($J$50:$K$50) -> 5.1436014 | O53: =+$C$53*AVERAGE($J$50:$K$50) -> 5.1436014 | P53: =+$C$53*AVERAGE($J$50:$K$50) -> 5.1436014
B54: Producción por nuevas reservas | D54: Miles TMF | L54: 0 | M54: =11*50% -> 5.5 | N54: =11*100% -> 11 | O54: =11*100% -> 11 | P54: =11*100% -> 11
...

Sheet Capex
C2: Volcan Minera | H2: Año | J2: 2019 | K2: 2020 | L2: 2021 | M2: 2022 | N2: 2023 | O2: 2024 | P2: 2025 | Q2: 2026 | R2: 2027 | S2: 2028 | T2: 2029
C3: Capex | H3: Mes | J3: 43830 | K3: 44196 | L3: 44561 | M3: 44926 | N3: 45291 | O3: 45657 | P3: 46022 | Q3: 46387 | R3: 46752 | S3: 47118 | T3: 47483
J4: Histórico | K4: Histórico | L4: Histórico | M4: Histórico | N4: Histórico | O4: Histórico | P4: Proyección | Q4: Proyección | R4: Proyección | S4: Proyección | T4: Proyección
A5: x | B5: Resumen
C7: A) Propiedad, planta y equipo (PPE),neto
C8: PPE,bruto | H8: USD mm | J8: =J50 -> 1388.181 | K8: =K50 -> 1859.667 | L8: =L50 -> 1929.62 | M8: =M50 -> 1816.027 | N8: =N50 -> 1945.957 | O8: =O50 -> 1935.681 | P8: =P50 -> 2026.3564 | Q8: =Q50 -> 2131.125 | ... T8: =T50 -> 2483.788
C9: Depreciación acumulada | H9: USD mm | J9: =-J77 -> -711.391 | K9: =-K77 -> -1087.604 | L9: =-L77 -> -1173.101 | M9: =-M77 -> -1003.115 | N9: =-N77 -> -1174.179 | O9: =-O77 -> -1252.56 | P9: =-P77 -> -1253.2908 | Q9: =-Q77 -> -1255.5966 | ... T9: =-T77 -> -1268.1666
C10: Deterioro acumulado | H10: USD mm | J10: =J101 -> -19.613 | K10: =K101 -> -10.408 | L10: =L101 -> -11.386 | M10: =M101 -> 43.921 | N10: =N101 -> 8.576 | O10: =O101 -> 0 | P10: =P101 -> 0 | Q10: =Q101 -> 0 | ... T10: =T101 -> 0
C11: PPE,neto | H11: USD mm | J11: =J8+J9+J10 -> 657.177 | K11: =K8+K9+K10 -> 761.655 | L11: =L8+L9+L10 -> 745.133 | M11: =M8+M9+M10 -> 856.833 | N11: =N8+N9+N10 -> 780.354 | O11: =O8+O9+O10 -> 683.121 | P11: =SUM(P8:P10) -> 773.06565 | Q11: =SUM(Q8:Q10) -> 875.52842 | R11: =SUM(R8:R10) -> 988.57793 | S11: =SUM(S8:S10) -> 1100.6902 | T11: =SUM(T8:T10) -> 1215.6214
C13: B) Derecho de uso, neto | H13: USD mm
C14: Derecho de uso, bruto | H14: USD mm | J14: =J379 | K14: =K379 -> 39.327 | L14: =L379 -> 44.253 | M14: =M379 -> 20.828 | N14: =N379 -> 24.646 | O14: =O379 -> 25.984 | P14: =P379 -> 36.477028 | Q14: =Q379 -> 48.600935 | ... T14: =T379 -> 89.411363
C15: Depreciación acumulada | H15: USD mm | J15: =J383 | K15: =K383 -> -35.042 | L15: =L383 -> -39.868 | M15: =M383 -> -9.443 | N15: =N383 -> -6.721 | O15: =O383 -> -10.322 | P15: =P383 -> -19.505486 | Q15: =Q383 -> -32.014282 | ... T15: =T383 -> -70.218655
C16: Derecho de uso neto | H16: USD mm | J16: =SUM(J14:J15) -> 0 | K16: =SUM(K14:K15) -> 4.285 | L16: =SUM(L14:L15) -> 4.385 | M16: =SUM(M14:M15) -> 11.385 | N16: =SUM(N14:N15) -> 17.925 | O16: =SUM(O14:O15) -> 15.662 | P16: =SUM(P14:P15) -> 16.971542 | Q16: =SUM(Q14:Q15) -> 16.586652 | ... T16: =SUM(T14:T15) -> 19.192708
C18: C) Intangible, neto
C19: Intangible, bruto | H19: USD mm | J19: =J410 -> 1376.45 | K19: =K410 -> 1572.165 | L19: =L410 -> 1676.34 | M19: =M410 -> 1672.381 | N19: =N410 -> 1751.595 | O19: =O410 -> 1831.858 | P19: =P410 -> 1921.02 | Q19: =Q410 -> 2024.0399 | ... T19: =T410 -> 2370.8166
C20: Amortización acumulada | H20: USD mm | J20: =J414 -> -596.328 | K20: =K414 -> -781.612 | L20: =L414 -> -874.357 | M20: =M414 -> -972.443 | N20: =N414 -> -1100.945 | O20: =O414 -> -1175.63 | P20: =P414 -> -1254.8934 | Q20: =Q414 -> -1338.2158 | ... T20: =T414 -> -1616.5257
C21: Intangible neto | H21: USD mm | J21: =SUM(J19:J20) -> 780.122 | K21: =SUM(K19:K20) -> 790.553 | L21: =SUM(L19:L20) -> 801.983 | M21: =SUM(M19:M20) -> 699.938 | N21: =SUM(N19:N20) -> 650.65 | O21: =SUM(O19:O20) -> 656.228 | P21: =SUM(P19:P20) -> 666.12658 | Q21: =SUM(Q19:Q20) -> 685.82414 | ... T21: =SUM(T19:T20) -> 754.29085
C23: D) Capex, por activo
C24: PPE | H24: USD mm | J24: =J62 -> 77.858 | K24: =K62 -> 61.572 | L24: =L62 -> 102.994 | M24: =M62 -> 129.494 | N24: =N62 -> 68.772 | O24: =O62 -> 70.752 | P24: =P62 -> 90.675413 | Q24: =Q62 -> 104.76863 | ... T24: =T62 -> 120.07779
C25: Derecho de uso | H25: USD mm | J25: =J377 | K25: =K377 -> 1.642 | L25: =L377 -> 4.325 | M25: =M377 -> 14.886 | N25: =N377 -> 12.248 | O25: =O377 -> 5.329 | P25: =P377 -> 10.493028 | Q25: =Q377 -> 12.123906 | ... T25: =T377 -> 13.895494
C26: Intangibles | H26: USD mm | J26: =J408 -> 110.115 | K26: =K408 -> 50.685 | L26: =L408 -> 83.762 | M26: =M408 -> 109.336 | N26: =N408 -> 89.385 | O26: =O408 -> 77.987 | P26: =P408 -> 89.161956 | Q26: =Q408 -> 103.01994 | ... T26: =T408 -> 118.07358
C27: Total capex | H27: USD mm | J27: =SUM(J24:J26) -> 187.973 | K27: =SUM(K24:K26) -> 113.899 | L27: =SUM(L24:L26) -> 191.081 | M27: =SUM(M24:M26) -> 253.716 | N27: =SUM(N24:N26) -> 170.405 | O27: =SUM(O24:O26) -> 154.068 | P27: =SUM(P24:P26) -> 190.3304 | Q27: =SUM(Q24:Q26) -> 219.91248 | ... T27: =SUM(T24:T26) -> 252.04687
C28: Total capex / ventas | H28: % | J28: =IFERROR(J27/'Supuestos '!F14,"-") -> 0.25279527 | K28: =IFERROR(K27/'Supuestos '!G14,"-") -> 0.21270886 | L28: =IFERROR(L27/'Supuestos '!H14,"-") -> 0.20384169 | M28: =IFERROR(M27/'Supuestos '!I14,"-") -> 0.26671404 | N28: =IFERROR(N27/'Supuestos '!J14,"-") -> 0.19296535 | O28: =IFERROR(O27/'Supuestos '!K14,"-") -> 0.16040045 | P28: =IFERROR(P27/'Supuestos '!L14,"-") -> 0.20637055 | Q28: =IFERROR(Q27/'Supuestos '!M14,"-") -> 0.20637055 | ... T28: =IFERROR(T27/'Supuestos '!P14,"-") -> 0.20637055
C30: E) D&aA, por activo
C31: Depreciación de PPE | H31: USD mm | J31: =J89 -> 113.456 | K31: =K89 -> 85.441 | L31: =L89 -> 96.667 | M31: =M89 -> 111.453 | N31: =N89 -> 109.222 | O31: =O89 -> 111.835 | P31: =P89 -> 0.73076098 | Q31: =Q89 -> 2.3058614 | ... T31: =T89 -> 5.146628
C32: Depreciación de Derecho de Uso | H32: USD mm | J32: =J381 | K32: =-K381 -> 16.218 | L32: =-L381 -> 4.826 | M32: =-M381 -> 7.086 | N32: =-N381 -> 5.438 | O32: =-O381 -> 7.444 | P32: =P381 -> -9.183486 | Q32: =Q381 -> -12.508796 | R32: =R381 -> -9.0097923 | S32: =S381 -> -12.586472 | T32: =T381 -> -16.608108
C33: Amortización de intangibles | H33: USD mm | J33: =-J412 -> 69.06 | K33: =-K412 -> 46.351 | L33: =-L412 -> 92.745 | M33: =-M412 -> 106.255 | N33: =-N412 -> 92.455 | O33: =-O412 -> 75.685 | P33: =-P412 -> 79.263372 | Q33: =-Q412 -> 83.322386 | ... T33: =-T412 -> 97.652769
C34: Total D&A | H34: USD mm | J34: =SUM(J31:J33) -> 182.516 | K34: =SUM(K31:K33) -> 148.01 | L34: =SUM(L31:L33) -> 194.238 | M34: =SUM(M31:M33) -> 224.794 | N34: =SUM(N31:N33) -> 207.115 | O34: =SUM(O31:O33) -> 194.964 | P34: =SUM(P31:P33) -> 70.810647 | Q34: =SUM(Q31:Q33) -> 73.119451 | ... T34: =SUM(T31:T33) -> 86.191289
C35: Total D&A / ventas | H35: % | J35: =IFERROR(J34/'Supuestos '!F14,"-") -> 0.24545643 | K35: =IFERROR(K34/'Supuestos '!G14,"-") -> 0.27641189 | L35: =IFERROR(L34/'Supuestos '!H14,"-") -> 0.20720952 | M35: =IFERROR(M34/'Supuestos '!I14,"-") -> 0.23631035 | N35: =IFERROR(N34/'Supuestos '!J14,"-") -> 0.23453548 | O35: =IFERROR(O34/'Supuestos '!K14,"-") -> 0.20297734 | P35: =IFERROR(P34/'Supuestos '!L14,"-") -> 0.076778234 | Q35: =IFERROR(Q34/'Supuestos '!M14,"-") -> 0.068616848 | ... T35: =IFERROR(T34/'Supuestos '!P14,"-") -> 0.07057157
A38: x | B38: A) Desglose de PPE por activo
C40: PPE bruto (costo)
B41: 1 | C41: Terreno | H41: USD mm | J41: =31353/1000 -> 31.353 | K41: =31498/1000 -> 31.498 | L41: =23537/1000 -> 23.537 | M41: =23919/1000 -> 23.919 | N41: =23573/1000 -> 23.573 | O41: =23106/1000 -> 23.106 | P41: =O41+P53 -> 23.310311 | Q41: =P41+Q53 -> 23.546377 | R41: =Q41+R53 -> 23.808408 | S41: =+R41+S53 -> 24.07044 | T41: =+S41+T53 -> 24.341001
B42: 2 | C42: Edificios y otras construcciones | H42: USD mm | J42: =747170/1000 -> 747.17 | K42: =940701/1000 -> 940.701 | L42: =976667/1000 -> 976.667 | M42: =1078997/1000 -> 1078.997 | N42: =1200955/1000 -> 1200.955 | O42: =1175308/1000 -> 1175.308 | P42: =O42+P54 -> 1178.8825 | Q42: =P42+Q54 -> 1183.0126 | R42: =Q42+R54 -> 1187.597 | S42: =+R42+S54 -> 1192.1814 | T42: =+S42+T54 -> 1196.915
B43: 3 | C43: Infraestructura de programa de manejo ambiental | H43: USD mm | J43: =11773/1000 -> 11.773 | K43: =22281/1000 -> 22.281 | L43: =22281/1000 -> 22.281 | M43: =259/1000 -> 0.259 | N43: =680/1000 -> 0.68 | O43: =680/1000 -> 0.68 | P43: =O43+P55 -> 0.68 | Q43: =P43+Q55 -> 0.68 | R43: =Q43+R55 -> 0.68 | S43: =+R43+S55 -> 0.68 | T43: =+S43+T55 -> 0.68
B44: 4 | C44: Maquinaria y equipo | H44: USD mm | J44: =167681/1000 -> 167.681 | K44: =285931/1000 -> 285.931 | L44: =300338/1000 -> 300.338 | M44: =193491/1000 -> 193.491 | N44: =187986/1000 -> 187.986 | O44: =178080/1000 -> 178.08 | P44: =O44+P56 -> 184.07752 | Q44: =P44+Q56 -> 191.0072 | R44: =Q44+R56 -> 198.69911 | S44: =+R44+S56 -> 206.39101 | T44: =+S44+T56 -> 214.33328
B45: 5 | C45: Unidades de transporte | H45: USD mm | J45: =4223/1000 -> 4.223 | K45: =11172/1000 -> 11.172 | L45: =11561/1000 -> 11.561 | M45: =3500/1000 -> 3.5 | N45: =3320/1000 -> 3.32 | O45: =2916/1000 -> 2.916 | P45: =O45+P57 -> 2.9668216 | Q45: =P45+Q57 -> 3.0255421 | R45: =Q45+R57 -> 3.0907215 | S45: =+R45+S57 -> 3.155901 | T45: =+S45+T57 -> 3.2232019
B46: 6 | C46: Muebles y enseres | H46: USD mm | J46: =12780/1000 -> 12.78 | K46: =15265/1000 -> 15.265 | L46: =16030/1000 -> 16.03 | M46: =10485/1000 -> 10.485 | N46: =8937/1000 -> 8.937 | O46: =8927/1000 -> 8.927 | P46: =O46+P58 -> 9.1068783 | Q46: =P46+Q58 -> 9.3147141 | R46: =Q46+R58 -> 9.5454107 | S46: =+R46+S58 -> 9.7761073 | T46: =+S46+T58 -> 10.014313
B47: 7 | C47: Equipos diversos | H47: USD mm | J47: =355816/1000 -> 355.816 | K47: =479759/1000 -> 479.759 | L47: =497908/1000 -> 497.908 | M47: =399352/1000 -> 399.352 | N47: =430633/1000 -> 430.633 | O47: =444796/1000 -> 444.796 | P47: =O47+P59 -> 460.8316 | Q47: =P47+Q59 -> 479.35953 | R47: =Q47+R59 -> 499.92542 | S47: =+R47+S59 -> 520.49132 | T47: =+S47+T59 -> 541.72661
B48: 8 | C48: Unidades por recibir | H48: USD mm | J48: =3724/1000 -> 3.724 | K48: =9326/1000 -> 9.326 | L48: =1602/1000 -> 1.602 | M48: =1620/1000 -> 1.62 | N48: =3244/1000 -> 3.244 | O48: =565/1000 -> 0.565 | P48: =O48+P60 -> 1.7840883 | Q48: =P48+Q60 -> 3.1926532 | R48: =Q48+R60 -> 4.7561523 | S48: =+R48+S60 -> 6.3196514 | T48: =+S48+T60 -> 7.9340409
B49: 9 | C49: Obras en curso | H49: USD mm | J49: =53661/1000 -> 53.661 | K49: =63734/1000 -> 63.734 | L49: =79696/1000 -> 79.696 | M49: =104404/1000 -> 104.404 | N49: =86629/1000 -> 86.629 | O49: =101303/1000 -> 101.303 | P49: =O49+P61 -> 164.71668 | Q49: =P49+Q61 -> 237.98642 | R49: =Q49+R61 -> 319.31541 | S49: =+R49+S61 -> 400.64441 | T49: =+S49+T61 -> 484.62059
...

Sheet Wacc
B2: VOLCAN COMPAÑÍA MINERA
B3: Análisis WACC
B4: (US$ millones)
B6: Cálculo de la WACC | G6: Empresas comparables beta desapalancado
B7: Estructura de capital del Target | G7: Empresas | H7: Ticket | I7: País | J7: Beta apalancado | K7: Total deuda (Millones) | L7: Market Equity(Millones) | M7: Debt/ Equity | N7: Tax Rate | O7: Beta desapalancado
G8: Coeur Mining Inc DRC | H8: CDE | I8: Estados Unidos | J8: 1.98 | K8: 528.5 | L8: 2150 | M8: =K8/L8 -> 0.24581395 | N8: 0 | O8: =IFERROR(J8/((1+M8)*(1-N8)),"-") -> 1.5893224
B9: Deuda / (Deuda + Patrimonio) | E9: =(Buildup!E57+Buildup!E67)/(Buildup!E57+Buildup!E67+Buildup!E83) -> 0.5838733 | G9: Endeavour Silver Corp | H9: EDR | I9: Canadá | J9: 1.35 | K9: 5.8 | L9: 1020 | M9: =K9/L9 -> 0.0056862745 | N9: 0.6 | O9: =IFERROR(J9/((1+M9)*(1-N9)),"-") -> 3.3559173
B10: Patrimonio / (Deuda + Patrimonio) | E10: =1-E9 -> 0.4161267 | G10: Eldorado Gold Corp | H10: ELD | I10: Canadá | J10: 0.85 | K10: 592.5 | L10: 2800 | M10: =K10/L10 -> 0.21160714 | N10: 0.35 | O10: =IFERROR(J10/((1+M10)*(1-N10)),"-") -> 1.0793039
G11: Fortuna Mining CorpFortuna Mining Corp | H11: FVI | I11: Canadá | J11: 1.1 | K11: 165 | L11: 1350 | M11: =K11/L11 -> 0.12222222 | N11: 0.5 | O11: =IFERROR(J11/((1+M11)*(1-N11)),"-") -> 1.960396
B12: Costo de deuda (Kd) | G12: Buenaventura S.A.A | H12: BUENAVC1 | I12: Perú | J12: 1.3 | K12: 598 | L12: 3100 | M12: =K12/L12 -> 0.19290323 | N12: 0.39 | O12: =IFERROR(J12/((1+M12)*(1-N12)),"-") -> 1.7865217
B13: Costo de deuda ( US$ ) | E13: ='Supuestos '!K170 -> 0.1019625 | G13: Industrias Penoles SAB de CV | H13: IPOA.F | I13: México | J13: 0.75 | K13: 1950 | L13: 6500 | M13: =K13/L13 -> 0.3 | N13: 0.3 | O13: =IFERROR(J13/((1+M13)*(1-N13)),"-") -> 0.82417582
B14: Tasa de impuestos | E14: 0.295
B15: Costo de deuda después de impuesto ( US$ ) | E15: =E13*(1-E14) -> 0.071883563 | G15: Promedio | J15: =AVERAGE(J8:J13) -> 1.2216667 | K15: =AVERAGE(K8:K13) -> 639.96667 | L15: =AVERAGE(L8:L13) -> 2820 | M15: =AVERAGE(M8:M13) -> 0.17970547 | N15: =AVERAGE(N8:N13) -> 0.35666667 | O15: =AVERAGE(O8:O13) -> 1.7659395
G16: Mediana | J16: =MEDIAN(J8:J13) -> 1.2 | K16: =MEDIAN(K8:K13) -> 560.5 | L16: =MEDIAN(L8:L13) -> 2475 | M16: =MEDIAN(M8:M13) -> 0.20225518 | N16: =MEDIAN(N8:N13) -> 0.37 | O16: =MEDIAN(O8:O13) -> 1.6879221
B17: Costo de equity (Ke)
B18: Tasa libe de riesgo (1) | E18: 0.0458 | G18: Beta desapalancado del sector según Damodaran | I18: 0.91
B19: Rendimiento esperado del mercado (Rm) (2) | E19: 0.1355
B20: Rendimiento esperado del bono del tesoro (Rf) | E20: 0.0652 | G20: Beta apalancado del Target
B21: Prima de Riesgo de Mercado (ERP) | E21: =E19-E20 -> 0.0703 | K21: Promedio de | L21: Deuda/ | M21: Tasa de | N21: Beta
B22: Beta apalacando | E22: =N25 -> 1.6264277 | K22: beta | L22: Patrimonio del | M22: impuestos del | N22: apalancado
B23: Riesgo país (Rp) (5) | E23: 0.0126 | K23: desapalancado | L23: Target | M23: Target
B24: Costo de equity (Ke) (US$) | E24: =E18+E22*E21+E23 -> 0.17273787 | G24: Beta apalancado, según comparables | K24: =O15 -> 1.7659395 | L24: =E9/E10 -> 1.4031143 | M24: =N15 -> 0.35666667 | N24: =K24*(1+L24)*(1-M24) -> 2.7301487
B25: Riesgo de divisa | E25: =E52 -> 0.01541 | G25: Beta apalancado, según Damodaran | K25: 0.96 | L25: =L24 -> 1.4031143 | M25: =E14 -> 0.295 | N25: =K25*(1+L25)*(1-M25) -> 1.6264277
B26: Costo de equity (Ke) ( PEN) | E26: =E24+E25 -> 0.18814787
G27: Análisis de sensibilidad de la WACC
B28: WACC (US$) | E28: =E15*E9+E24*E10 -> 0.11385173
K29: Costo de deuda antes de impuestos
I30: D/(D+E) | J30: =E28 -> 0.11385173 | K30: =L30-0.5% -> 0.092 | L30: =M30-0.5% -> 0.097 | M30: 0.102 | N30: =M30+0.5% -> 0.107 | O30: =N30+0.5% -> 0.112
J31: =J32-10% -> 0.384 | K31: 0.10845968 | L31: 0.10981328 | M31: 0.11116688 | N31: 0.11252048 | O31: 0.11387408
J32: =J33-10% -> 0.484 | K32: 0.10910568 | L32: 0.11081178 | M32: 0.11251788 | N32: 0.11422398 | O32: 0.11593008
J33: 0.584 | K33: 0.10975168 | L33: 0.11181028 | M33: 0.11386888 | N33: 0.11592748 | O33: 0.11798608
J34: =J33+10% -> 0.684 | K34: 0.11039768 | L34: 0.11280878 | M34: 0.11521988 | N34: 0.11763098 | O34: 0.12004208
J35: =J34+10% -> 0.784 | K35: 0.11104368 | L35: 0.11380728 | M35: 0.11657088 | N35: 0.11933448 | O35: 0.12209808
B38: (1) Rendimiento del bono del Tesoro USA a 20 años, obtenido en Treasury.gov.
B39: (2) Fuente: Damodaran
B40: (3) Fuente: Damodaran
B41: (4) Fuente: Damodaran
B42: (5) Resultado del EMBIG Perú al 18/09/2025, obtenido del BCRP
B44: Riesgo país (Rp)
B45: Bono emitido por Estados Unidos en US$ | E45: =E18 -> 0.0458
...

Sheet Comparables
B2: Empresas | C2: País | D2: Nombre | E2: Ticket | F2: EV/EBITDA | G2: EV/Ventas | H2: PER | I2: Market Cap (Millones)
B3: Empresa 1 | C3: Perú | D3: Compania de Minas Buenaventura SAA | E3: BUENAVC1 | F3: 8.2 | G3: 3,0 | H3: 12.3 | I3: =18121 -> 18121
B4: Empresa 2 | C4: Estados Unidos | D4: Coeur Mining Inc DRC | E4: CDE | F4: 12.8 | G4: 5,3 | H4: 21.7 | I4: 29925
B5: Empresa 3 | C5: Canadá | D5: Endeavour Silver Corp | E5: EDR | F5: 56.8 | G5: 9,3 | H5: - | I5: 7330
B6: Empresa 4 | C6: =C7 -> Canadá | D6: Eldorado Gold Corp | E6: ELD | F6: 5.6 | G6: 3,1 | H6: 13.3 | I6: 16862
B7: Empresa 5 | C7: Canadá | D7: Fortuna Mining Corp | E7: FVI | F7: 4.1 | G7: 1,9 | H7: 14.1 | I7: 8106
B8: Empresa 6 | C8: México | D8: Industrias Penoles SAB de CV | E8: IPOA.F | F8: 6.4 | G8: 2,2 | H8: 16.7 | I8: 51770
B9: Fuente: Investing.com
E11: Mediana | F11: =MEDIAN(F3:F8) -> 7.3 | H11: =MEDIAN(H3:H8) -> 14.1
E12: Promedio | F12: =AVERAGE(F3:F8) -> 15.65 | H12: =AVERAGE(H3:H8) -> 15.62

Sheet Valoración
B2: VOLCAN COMPAÑÍA MINERA
B3: Análisis de flujos de caja descontados (DCF)
B4: (USD millones)
E6: Periodo histórico | I6: CAGR | K6: Periodo de proyección | P6: CAGR
E7: 2020 | F7: 2021 | G7: 2022 | H7: 2023 | I7: ('20 - '23) | J7: 2024 | K7: 2025 | L7: 2026 | M7: 2027 | N7: 2028 | O7: 2029 | P7: ('24 - '29)
